<sdf version='1.11'>
  <model name='Moonzy'>
    <link name='base_link'>
      <inertial>
        <pose>0 0 0.20821917808219181 0 0 0</pose>
        <mass>36.5</mass>
        <inertia>
          <ixx>0.6267717465753424</ixx>
          <ixy>0</ixy>
          <ixz>0</ixz>
          <iyy>0.6267717465753424</iyy>
          <iyz>0</iyz>
          <izz>0.57687500000000003</izz>
        </inertia>
      </inertial>
      <collision name='base_link_fixed_joint_lump__stomach_collision'>
        <pose>0 0 0.20000000000000001 0 0 0</pose>
        <geometry>
          <sphere>
            <radius>0.20000000000000001</radius>
          </sphere>
        </geometry>
      </collision>
      <collision name='base_link_fixed_joint_lump__neck_collision_1'>
        <pose>0 0 0.40000000000000002 0 0 0</pose>
        <geometry>
          <cylinder>
            <length>0.080000000000000002</length>
            <radius>0.14999999999999999</radius>
          </cylinder>
        </geometry>
      </collision>
      <visual name='base_link_fixed_joint_lump__stomach_visual'>
        <pose>0 0 0.20000000000000001 0 0 0</pose>
        <geometry>
          <sphere>
            <radius>0.20000000000000001</radius>
          </sphere>
        </geometry>
        <material>
          <diffuse>1 0.784313738 1 1</diffuse>
          <ambient>1 0.784313738 1 1</ambient>
        </material>
      </visual>
      <visual name='base_link_fixed_joint_lump__neck_visual_1'>
        <pose>0 0 0.40000000000000002 0 0 0</pose>
        <geometry>
          <cylinder>
            <length>0.080000000000000002</length>
            <radius>0.14999999999999999</radius>
          </cylinder>
        </geometry>
        <material>
          <diffuse>1 0.784313738 1 1</diffuse>
          <ambient>1 0.784313738 1 1</ambient>
        </material>
      </visual>
    </link>
    <joint name='left_arm_joint' type='revolute'>
      <pose relative_to='base_link'>0 0.14999999999999999 0.25 1.5707963267948959 0 0</pose>
      <parent>base_link</parent>
      <child>left_arm</child>
      <axis>
        <xyz>1 0 0</xyz>
        <limit>
          <lower>-0.78539816339744828</lower>
          <upper>0.78539816339744828</upper>
          <effort>1000</effort>
          <velocity>0.5</velocity>
        </limit>
        <dynamics>
          <spring_reference>0</spring_reference>
          <spring_stiffness>0</spring_stiffness>
        </dynamics>
      </axis>
    </joint>
    <link name='left_arm'>
      <pose relative_to='left_arm_joint'>0 0 0 0 0 0</pose>
      <inertial>
        <pose>0 0 -0.1111111111111111 0 0 0</pose>
        <mass>0.90000000000000002</mass>
        <inertia>
          <ixx>0.0038645555555555529</ixx>
          <ixy>0</ixy>
          <ixz>0</ixz>
          <iyy>0.0038645555555555529</iyy>
          <iyz>0</iyz>
          <izz>0.00055400000000000013</izz>
        </inertia>
      </inertial>
      <collision name='left_arm_collision'>
        <pose>0 0 -0.10000000000000001 0 0 0</pose>
        <geometry>
          <cylinder>
            <length>0.20000000000000001</length>
            <radius>0.035000000000000003</radius>
          </cylinder>
        </geometry>
      </collision>
      <collision name='left_arm_fixed_joint_lump__left_paw_collision_1'>
        <pose>0 0 -0.20000000000000001 0 0 0</pose>
        <geometry>
          <sphere>
            <radius>0.040000000000000001</radius>
          </sphere>
        </geometry>
      </collision>
      <visual name='left_arm_visual'>
        <pose>0 0 -0.10000000000000001 0 0 0</pose>
        <geometry>
          <cylinder>
            <length>0.20000000000000001</length>
            <radius>0.035000000000000003</radius>
          </cylinder>
        </geometry>
        <material>
          <diffuse>1 0.784313738 1 1</diffuse>
          <ambient>1 0.784313738 1 1</ambient>
        </material>
      </visual>
      <visual name='left_arm_fixed_joint_lump__left_paw_visual_1'>
        <pose>0 0 -0.20000000000000001 0 0 0</pose>
        <geometry>
          <sphere>
            <radius>0.040000000000000001</radius>
          </sphere>
        </geometry>
        <material>
          <diffuse>1 1 1 1</diffuse>
          <ambient>1 1 1 1</ambient>
        </material>
      </visual>
    </link>
    <joint name='head_swivel' type='revolute'>
      <pose relative_to='base_link'>0 0 0.55000000000000004 0 0 0</pose>
      <parent>base_link</parent>
      <child>head</child>
      <axis>
        <xyz>0 0 1</xyz>
        <limit>
          <lower>-1.570796326794897</lower>
          <upper>1.570796326794897</upper>
          <effort>1000</effort>
          <velocity>0.5</velocity>
        </limit>
        <dynamics>
          <spring_reference>0</spring_reference>
          <spring_stiffness>0</spring_stiffness>
        </dynamics>
      </axis>
    </joint>
    <link name='head'>
      <pose relative_to='head_swivel'>0 0 0 0 0 0</pose>
      <inertial>
        <pose>0 0 0 0 0 0</pose>
        <mass>3</mass>
        <inertia>
          <ixx>0.027</ixx>
          <ixy>0</ixy>
          <ixz>0</ixz>
          <iyy>0.027</iyy>
          <iyz>0</iyz>
          <izz>0.027</izz>
        </inertia>
      </inertial>
      <collision name='head_collision'>
        <pose>0 0 0 0 0 0</pose>
        <geometry>
          <sphere>
            <radius>0.14999999999999999</radius>
          </sphere>
        </geometry>
      </collision>
      <visual name='head_visual'>
        <pose>0 0 0 0 0 0</pose>
        <geometry>
          <sphere>
            <radius>0.14999999999999999</radius>
          </sphere>
        </geometry>
        <material>
          <diffuse>1 0.784313738 1 1</diffuse>
          <ambient>1 0.784313738 1 1</ambient>
        </material>
      </visual>
    </link>
    <joint name='left_lower_ear_joint' type='revolute'>
      <pose relative_to='head'>0 0.10000000000000001 0.050000000000000003 1.6580627893946129 0 0</pose>
      <parent>head</parent>
      <child>left_lower_ear</child>
      <axis>
        <xyz>1 0 0</xyz>
        <limit>
          <lower>-0.05235987755982989</lower>
          <upper>0.05235987755982989</upper>
          <effort>1000</effort>
          <velocity>0.5</velocity>
        </limit>
        <dynamics>
          <spring_reference>0</spring_reference>
          <spring_stiffness>0</spring_stiffness>
        </dynamics>
      </axis>
    </joint>
    <link name='left_lower_ear'>
      <pose relative_to='left_lower_ear_joint'>0 0 0 0 0 0</pose>
      <inertial>
        <pose>0 0 -0.075000000000000011 0 0 0</pose>
        <mass>1</mass>
        <inertia>
          <ixx>0.0016997916666666661</ixx>
          <ixy>0</ixy>
          <ixz>0</ixz>
          <iyy>0.0016997916666666661</iyy>
          <iyz>0</iyz>
          <izz>0.00091124999999999995</izz>
        </inertia>
      </inertial>
      <collision name='left_lower_ear_collision'>
        <pose>0 0 -0.050000000000000003 0 0 0</pose>
        <geometry>
          <cylinder>
            <length>0.10000000000000001</length>
            <radius>0.044999999999999998</radius>
          </cylinder>
        </geometry>
      </collision>
      <collision name='left_lower_ear_tip_collision_1'>
        <pose>0 0 -0.10000000000000001 0 0 0</pose>
        <geometry>
          <sphere>
            <radius>0.044999999999999998</radius>
          </sphere>
        </geometry>
      </collision>
      <visual name='left_lower_ear_visual'>
        <pose>0 0 -0.050000000000000003 0 0 0</pose>
        <geometry>
          <cylinder>
            <length>0.10000000000000001</length>
            <radius>0.044999999999999998</radius>
          </cylinder>
        </geometry>
        <material>
          <diffuse>1 0.637254953 1 1</diffuse>
          <ambient>1 0.637254953 1 1</ambient>
        </material>
      </visual>
      <visual name='left_lower_ear_tip_visual_1'>
        <pose>0 0 -0.10000000000000001 0 0 0</pose>
        <geometry>
          <sphere>
            <radius>0.044999999999999998</radius>
          </sphere>
        </geometry>
        <material>
          <diffuse>1 0.637254953 1 1</diffuse>
          <ambient>1 0.637254953 1 1</ambient>
        </material>
      </visual>
    </link>
    <joint name='left_upper_ear_joint' type='revolute'>
      <pose relative_to='head'>0 0.080000000000000002 0.10000000000000001 2.3561944901923448 0 0</pose>
      <parent>head</parent>
      <child>left_upper_ear</child>
      <axis>
        <xyz>1 0 0</xyz>
        <limit>
          <lower>-0.05235987755982989</lower>
          <upper>0.05235987755982989</upper>
          <effort>1000</effort>
          <velocity>0.5</velocity>
        </limit>
        <dynamics>
          <spring_reference>0</spring_reference>
          <spring_stiffness>0</spring_stiffness>
        </dynamics>
      </axis>
    </joint>
    <link name='left_upper_ear'>
      <pose relative_to='left_upper_ear_joint'>0 0 0 0 0 0</pose>
      <inertial>
        <pose>0 0 -0.075000000000000011 0 0 0</pose>
        <mass>1</mass>
        <inertia>
          <ixx>0.0016997916666666661</ixx>
          <ixy>0</ixy>
          <ixz>0</ixz>
          <iyy>0.0016997916666666661</iyy>
          <iyz>0</iyz>
          <izz>0.00091124999999999995</izz>
        </inertia>
      </inertial>
      <collision name='left_upper_ear_collision'>
        <pose>0 0 -0.050000000000000003 0 0 0</pose>
        <geometry>
          <cylinder>
            <length>0.10000000000000001</length>
            <radius>0.044999999999999998</radius>
          </cylinder>
        </geometry>
      </collision>
      <collision name='left_upper_ear_tip_collision_1'>
        <pose>0 0 -0.10000000000000001 0 0 0</pose>
        <geometry>
          <sphere>
            <radius>0.044999999999999998</radius>
          </sphere>
        </geometry>
      </collision>
      <visual name='left_upper_ear_visual'>
        <pose>0 0 -0.050000000000000003 0 0 0</pose>
        <geometry>
          <cylinder>
            <length>0.10000000000000001</length>
            <radius>0.044999999999999998</radius>
          </cylinder>
        </geometry>
        <material>
          <diffuse>1 0.637254953 1 1</diffuse>
          <ambient>1 0.637254953 1 1</ambient>
        </material>
      </visual>
      <visual name='left_upper_ear_tip_visual_1'>
        <pose>0 0 -0.10000000000000001 0 0 0</pose>
        <geometry>
          <sphere>
            <radius>0.044999999999999998</radius>
          </sphere>
        </geometry>
        <material>
          <diffuse>1 0.637254953 1 1</diffuse>
          <ambient>1 0.637254953 1 1</ambient>
        </material>
      </visual>
    </link>
    <joint name='right_lower_ear_joint' type='revolute'>
      <pose relative_to='head'>0 -0.10000000000000001 0.050000000000000003 1.48352986419518 0 0</pose>
      <parent>head</parent>
      <child>right_lower_ear</child>
      <axis>
        <xyz>1 0 0</xyz>
        <limit>
          <lower>-0.05235987755982989</lower>
          <upper>0.05235987755982989</upper>
          <effort>1000</effort>
          <velocity>0.5</velocity>
        </limit>
        <dynamics>
          <spring_reference>0</spring_reference>
          <spring_stiffness>0</spring_stiffness>
        </dynamics>
      </axis>
    </joint>
    <link name='right_lower_ear'>
      <pose relative_to='right_lower_ear_joint'>0 0 0 0 0 0</pose>
      <inertial>
        <pose>0 0 0.075000000000000011 0 0 0</pose>
        <mass>1</mass>
        <inertia>
          <ixx>0.0016997916666666661</ixx>
          <ixy>0</ixy>
          <ixz>0</ixz>
          <iyy>0.0016997916666666661</iyy>
          <iyz>0</iyz>
          <izz>0.00091124999999999995</izz>
        </inertia>
      </inertial>
      <collision name='right_lower_ear_collision'>
        <pose>0 0 0.050000000000000003 0 0 0</pose>
        <geometry>
          <cylinder>
            <length>0.10000000000000001</length>
            <radius>0.044999999999999998</radius>
          </cylinder>
        </geometry>
      </collision>
      <collision name='right_lower_ear_tip_collision_1'>
        <pose>0 0 0.10000000000000001 0 0 0</pose>
        <geometry>
          <sphere>
            <radius>0.044999999999999998</radius>
          </sphere>
        </geometry>
      </collision>
      <visual name='right_lower_ear_visual'>
        <pose>0 0 0.050000000000000003 0 0 0</pose>
        <geometry>
          <cylinder>
            <length>0.10000000000000001</length>
            <radius>0.044999999999999998</radius>
          </cylinder>
        </geometry>
        <material>
          <diffuse>1 0.637254953 1 1</diffuse>
          <ambient>1 0.637254953 1 1</ambient>
        </material>
      </visual>
      <visual name='right_lower_ear_tip_visual_1'>
        <pose>0 0 0.10000000000000001 0 0 0</pose>
        <geometry>
          <sphere>
            <radius>0.044999999999999998</radius>
          </sphere>
        </geometry>
        <material>
          <diffuse>1 0.637254953 1 1</diffuse>
          <ambient>1 0.637254953 1 1</ambient>
        </material>
      </visual>
    </link>
    <joint name='right_upper_ear_joint' type='revolute'>
      <pose relative_to='head'>0 -0.080000000000000002 0.10000000000000001 0.7853981633974485 0 0</pose>
      <parent>head</parent>
      <child>right_upper_ear</child>
      <axis>
        <xyz>1 0 0</xyz>
        <limit>
          <lower>-0.05235987755982989</lower>
          <upper>0.05235987755982989</upper>
          <effort>1000</effort>
          <velocity>0.5</velocity>
        </limit>
        <dynamics>
          <spring_reference>0</spring_reference>
          <spring_stiffness>0</spring_stiffness>
        </dynamics>
      </axis>
    </joint>
    <link name='right_upper_ear'>
      <pose relative_to='right_upper_ear_joint'>0 0 0 0 0 0</pose>
      <inertial>
        <pose>0 0 0.075000000000000011 0 0 0</pose>
        <mass>1</mass>
        <inertia>
          <ixx>0.0016997916666666661</ixx>
          <ixy>0</ixy>
          <ixz>0</ixz>
          <iyy>0.0016997916666666661</iyy>
          <iyz>0</iyz>
          <izz>0.00091124999999999995</izz>
        </inertia>
      </inertial>
      <collision name='right_upper_ear_collision'>
        <pose>0 0 0.050000000000000003 0 0 0</pose>
        <geometry>
          <cylinder>
            <length>0.10000000000000001</length>
            <radius>0.044999999999999998</radius>
          </cylinder>
        </geometry>
      </collision>
      <collision name='right_upper_ear_tip_collision_1'>
        <pose>0 0 0.10000000000000001 0 0 0</pose>
        <geometry>
          <sphere>
            <radius>0.044999999999999998</radius>
          </sphere>
        </geometry>
      </collision>
      <visual name='right_upper_ear_visual'>
        <pose>0 0 0.050000000000000003 0 0 0</pose>
        <geometry>
          <cylinder>
            <length>0.10000000000000001</length>
            <radius>0.044999999999999998</radius>
          </cylinder>
        </geometry>
        <material>
          <diffuse>1 0.637254953 1 1</diffuse>
          <ambient>1 0.637254953 1 1</ambient>
        </material>
      </visual>
      <visual name='right_upper_ear_tip_visual_1'>
        <pose>0 0 0.10000000000000001 0 0 0</pose>
        <geometry>
          <sphere>
            <radius>0.044999999999999998</radius>
          </sphere>
        </geometry>
        <material>
          <diffuse>1 0.637254953 1 1</diffuse>
          <ambient>1 0.637254953 1 1</ambient>
        </material>
      </visual>
    </link>
    <joint name='right_arm_joint' type='revolute'>
      <pose relative_to='base_link'>0 -0.14999999999999999 0.25 1.5707963267948959 0 0</pose>
      <parent>base_link</parent>
      <child>right_arm</child>
      <axis>
        <xyz>1 0 0</xyz>
        <limit>
          <lower>-0.78539816339744828</lower>
          <upper>0.78539816339744828</upper>
          <effort>1000</effort>
          <velocity>0.5</velocity>
        </limit>
        <dynamics>
          <spring_reference>0</spring_reference>
          <spring_stiffness>0</spring_stiffness>
        </dynamics>
      </axis>
    </joint>
    <link name='right_arm'>
      <pose relative_to='right_arm_joint'>0 0 0 0 0 0</pose>
      <inertial>
        <pose>0 0 0.1111111111111111 0 0 0</pose>
        <mass>0.90000000000000002</mass>
        <inertia>
          <ixx>0.0038645555555555529</ixx>
          <ixy>0</ixy>
          <ixz>0</ixz>
          <iyy>0.0038645555555555529</iyy>
          <iyz>0</iyz>
          <izz>0.00055400000000000013</izz>
        </inertia>
      </inertial>
      <collision name='right_arm_collision'>
        <pose>0 0 0.10000000000000001 0 0 0</pose>
        <geometry>
          <cylinder>
            <length>0.20000000000000001</length>
            <radius>0.035000000000000003</radius>
          </cylinder>
        </geometry>
      </collision>
      <collision name='right_arm_fixed_joint_lump__right_paw_collision_1'>
        <pose>0 0 0.20000000000000001 0 0 0</pose>
        <geometry>
          <sphere>
            <radius>0.040000000000000001</radius>
          </sphere>
        </geometry>
      </collision>
      <visual name='right_arm_visual'>
        <pose>0 0 0.10000000000000001 0 0 0</pose>
        <geometry>
          <cylinder>
            <length>0.20000000000000001</length>
            <radius>0.035000000000000003</radius>
          </cylinder>
        </geometry>
        <material>
          <diffuse>1 0.784313738 1 1</diffuse>
          <ambient>1 0.784313738 1 1</ambient>
        </material>
      </visual>
      <visual name='right_arm_fixed_joint_lump__right_paw_visual_1'>
        <pose>0 0 0.20000000000000001 0 0 0</pose>
        <geometry>
          <sphere>
            <radius>0.040000000000000001</radius>
          </sphere>
        </geometry>
        <material>
          <diffuse>1 1 1 1</diffuse>
          <ambient>1 1 1 1</ambient>
        </material>
      </visual>
    </link>
    <joint name='stomach_to_left_leg' type='revolute'>
      <pose relative_to='base_link'>0.10000000000000001 0.10000000000000001 0.10000000000000001 0 1.5707963267948966 0</pose>
      <parent>base_link</parent>
      <child>left_leg</child>
      <axis>
        <xyz>0 1 0</xyz>
        <limit>
          <lower>-0.78539816339744828</lower>
          <upper>1.570796326794897</upper>
          <effort>1000</effort>
          <velocity>0.5</velocity>
        </limit>
        <dynamics>
          <spring_reference>0</spring_reference>
          <spring_stiffness>0</spring_stiffness>
        </dynamics>
      </axis>
    </joint>
    <link name='left_leg'>
      <pose relative_to='stomach_to_left_leg'>0 0 0 0 0 0</pose>
      <inertial>
        <pose>0 0 0.10000000000000001 0 0 0</pose>
        <mass>1</mass>
        <inertia>
          <ixx>0.0039583333333333337</ixx>
          <ixy>0</ixy>
          <ixz>0</ixz>
          <iyy>0.0039583333333333337</iyy>
          <iyz>0</iyz>
          <izz>0.00125</izz>
        </inertia>
      </inertial>
      <collision name='left_leg_collision'>
        <pose>0 0 0.10000000000000001 0 0 0</pose>
        <geometry>
          <cylinder>
            <length>0.20000000000000001</length>
            <radius>0.050000000000000003</radius>
          </cylinder>
        </geometry>
      </collision>
      <visual name='left_leg_visual'>
        <pose>0 0 0.10000000000000001 0 0 0</pose>
        <geometry>
          <cylinder>
            <length>0.20000000000000001</length>
            <radius>0.050000000000000003</radius>
          </cylinder>
        </geometry>
        <material>
          <diffuse>1 0.637254953 1 1</diffuse>
          <ambient>1 0.637254953 1 1</ambient>
        </material>
      </visual>
    </link>
    <joint name='left_wheel_joint' type='revolute'>
      <pose relative_to='left_leg'>0 0 0.20000000000000001 0 0 0</pose>
      <parent>left_leg</parent>
      <child>left_wheel</child>
      <axis>
        <xyz>0 1 0</xyz>
        <limit>
          <lower>-inf</lower>
          <upper>inf</upper>
        </limit>
        <dynamics>
          <spring_reference>0</spring_reference>
          <spring_stiffness>0</spring_stiffness>
        </dynamics>
      </axis>
    </joint>
    <link name='left_wheel'>
      <pose relative_to='left_wheel_joint'>0 0 0 0 0 0</pose>
      <inertial>
        <pose>0 0 0 0 0 0</pose>
        <mass>0.20000000000000001</mass>
        <inertia>
          <ixx>0.0003920000000000001</ixx>
          <ixy>0</ixy>
          <ixz>0</ixz>
          <iyy>0.0003920000000000001</iyy>
          <iyz>0</iyz>
          <izz>0.0003920000000000001</izz>
        </inertia>
      </inertial>
      <collision name='left_wheel_collision'>
        <pose>0 0 0 0 0 0</pose>
        <geometry>
          <sphere>
            <radius>0.070000000000000007</radius>
          </sphere>
        </geometry>
      </collision>
      <visual name='left_wheel_visual'>
        <pose>0 0 0 0 0 0</pose>
        <geometry>
          <sphere>
            <radius>0.070000000000000007</radius>
          </sphere>
        </geometry>
        <material>
          <diffuse>1 1 1 1</diffuse>
          <ambient>1 1 1 1</ambient>
        </material>
      </visual>
    </link>
    <joint name='stomach_to_right_leg' type='revolute'>
      <pose relative_to='base_link'>0.10000000000000001 -0.10000000000000001 0.10000000000000001 0 1.5707963267948966 0</pose>
      <parent>base_link</parent>
      <child>right_leg</child>
      <axis>
        <xyz>0 1 0</xyz>
        <limit>
          <lower>-0.78539816339744828</lower>
          <upper>1.570796326794897</upper>
          <effort>1000</effort>
          <velocity>0.5</velocity>
        </limit>
        <dynamics>
          <spring_reference>0</spring_reference>
          <spring_stiffness>0</spring_stiffness>
        </dynamics>
      </axis>
    </joint>
    <link name='right_leg'>
      <pose relative_to='stomach_to_right_leg'>0 0 0 0 0 0</pose>
      <inertial>
        <pose>0 0 0.10000000000000001 0 0 0</pose>
        <mass>1</mass>
        <inertia>
          <ixx>0.0039583333333333337</ixx>
          <ixy>0</ixy>
          <ixz>0</ixz>
          <iyy>0.0039583333333333337</iyy>
          <iyz>0</iyz>
          <izz>0.00125</izz>
        </inertia>
      </inertial>
      <collision name='right_leg_collision'>
        <pose>0 0 0.10000000000000001 0 0 0</pose>
        <geometry>
          <cylinder>
            <length>0.20000000000000001</length>
            <radius>0.050000000000000003</radius>
          </cylinder>
        </geometry>
      </collision>
      <visual name='right_leg_visual'>
        <pose>0 0 0.10000000000000001 0 0 0</pose>
        <geometry>
          <cylinder>
            <length>0.20000000000000001</length>
            <radius>0.050000000000000003</radius>
          </cylinder>
        </geometry>
        <material>
          <diffuse>1 0.637254953 1 1</diffuse>
          <ambient>1 0.637254953 1 1</ambient>
        </material>
      </visual>
    </link>
    <joint name='right_wheel_joint' type='revolute'>
      <pose relative_to='right_leg'>0 0 0.20000000000000001 0 0 0</pose>
      <parent>right_leg</parent>
      <child>right_wheel</child>
      <axis>
        <xyz>0 1 0</xyz>
        <limit>
          <lower>-inf</lower>
          <upper>inf</upper>
        </limit>
        <dynamics>
          <spring_reference>0</spring_reference>
          <spring_stiffness>0</spring_stiffness>
        </dynamics>
      </axis>
    </joint>
    <link name='right_wheel'>
      <pose relative_to='right_wheel_joint'>0 0 0 0 0 0</pose>
      <inertial>
        <pose>0 0 0 0 0 0</pose>
        <mass>0.20000000000000001</mass>
        <inertia>
          <ixx>0.0003920000000000001</ixx>
          <ixy>0</ixy>
          <ixz>0</ixz>
          <iyy>0.0003920000000000001</iyy>
          <iyz>0</iyz>
          <izz>0.0003920000000000001</izz>
        </inertia>
      </inertial>
      <collision name='right_wheel_collision'>
        <pose>0 0 0 0 0 0</pose>
        <geometry>
          <sphere>
            <radius>0.070000000000000007</radius>
          </sphere>
        </geometry>
      </collision>
      <visual name='right_wheel_visual'>
        <pose>0 0 0 0 0 0</pose>
        <geometry>
          <sphere>
            <radius>0.070000000000000007</radius>
          </sphere>
        </geometry>
        <material>
          <diffuse>1 1 1 1</diffuse>
          <ambient>1 1 1 1</ambient>
        </material>
      </visual>
    </link>
    <plugin name='gz::sim::systems::JointStatePublisher' filename='gz-sim-joint-state-publisher-system'/>
    <plugin name='gz::sim::systems::DiffDrive' filename='gz-sim-diff-drive-system'>
      <left_joint>left_wheel_joint</left_joint>
      <right_joint>right_wheel_joint</right_joint>
      <child_frame_id>Moonzy/base_link</child_frame_id>
      <wheel_separation>0.2</wheel_separation>
      <wheel_radius>0.07</wheel_radius>
      <odom_publish_frequency>10</odom_publish_frequency>
    </plugin>
    <frame name='neck_joint' attached_to='stomach'>
      <pose>0 0 0.20000000000000001 0 0 0</pose>
    </frame>
    <frame name='neck' attached_to='neck_joint'>
      <pose>0 0 0 0 0 0</pose>
    </frame>
    <frame name='left_lower_ear_tip_joint' attached_to='left_lower_ear'>
      <pose>0 0 -0.10000000000000001 0 0 0</pose>
    </frame>
    <frame name='left_lower_ear_tip' attached_to='left_lower_ear_tip_joint'>
      <pose>0 0 0 0 0 0</pose>
    </frame>
    <frame name='left_upper_ear_tip_joint' attached_to='left_upper_ear'>
      <pose>0 0 -0.10000000000000001 0 0 0</pose>
    </frame>
    <frame name='left_upper_ear_tip' attached_to='left_upper_ear_tip_joint'>
      <pose>0 0 0 0 0 0</pose>
    </frame>
    <frame name='right_lower_ear_tip_joint' attached_to='right_lower_ear'>
      <pose>0 0 0.10000000000000001 0 0 0</pose>
    </frame>
    <frame name='right_lower_ear_tip' attached_to='right_lower_ear_tip_joint'>
      <pose>0 0 0 0 0 0</pose>
    </frame>
    <frame name='right_upper_ear_tip_joint' attached_to='right_upper_ear'>
      <pose>0 0 0.10000000000000001 0 0 0</pose>
    </frame>
    <frame name='right_upper_ear_tip' attached_to='right_upper_ear_tip_joint'>
      <pose>0 0 0 0 0 0</pose>
    </frame>
    <frame name='stomach_to_base' attached_to='base_link'>
      <pose>0 0 0.20000000000000001 0 0 0</pose>
    </frame>
    <frame name='stomach' attached_to='stomach_to_base'>
      <pose>0 0 0 0 0 0</pose>
    </frame>
    <frame name='left_paw_joint' attached_to='left_arm'>
      <pose>0 0 -0.20000000000000001 0 0 0</pose>
    </frame>
    <frame name='left_paw' attached_to='left_paw_joint'>
      <pose>0 0 0 0 0 0</pose>
    </frame>
    <frame name='right_paw_joint' attached_to='right_arm'>
      <pose>0 0 0.20000000000000001 0 0 0</pose>
    </frame>
    <frame name='right_paw' attached_to='right_paw_joint'>
      <pose>0 0 0 0 0 0</pose>
    </frame>
  </model>
</sdf>
