<?xml version="1.0" ?>
<!-- =================================================================================== -->
<!-- |    This document was autogenerated by xacro from robot.urdf                     | -->
<!-- |    EDITING THIS FILE BY HAND IS NOT RECOMMENDED                                 | -->
<!-- =================================================================================== -->
<robot name="Moonzy" xmlns:xacro="http://www.ros.org/wiki/xacro">
  <!-- Define materials -->
  <material name="violet">
    <color rgba="0.9333333333333333 0.5098039215686274 0.9333333333333333 1"/>
  </material>
  <material name="plum">
    <color rgba="0.8666666666666667 0.6274509803921569 0.8666666666666667 1"/>
  </material>
  <material name="white">
    <color rgba="1 1 1 1"/>
  </material>
  <material name="green">
    <color rgba="0 1 0 1"/>
  </material>
  <!-- Some plugins for gazebo -->
  <gazebo>
    <plugin filename="gz-sim-joint-state-publisher-system" name="gz::sim::systems::JointStatePublisher">
        </plugin>
    <plugin filename="gz-sim-diff-drive-system" name="gz::sim::systems::DiffDrive">
      <left_joint>left_wheel_joint</left_joint>
      <right_joint>right_wheel_joint</right_joint>
      <child_frame_id>Moonzy/base_link</child_frame_id>
      <wheel_separation>0.2</wheel_separation>
      <wheel_radius>0.07</wheel_radius>
      <odom_publish_frequency>10</odom_publish_frequency>
    </plugin>
  </gazebo>
  <!-- Define all the links and joints -->
  <!-- Define base_link -->
  <link name="base_link">
  </link>
  <link name="stomach">
    <visual>
      <geometry>
        <sphere radius="0.2"/>
      </geometry>
      <material name="plum"/>
    </visual>
    <collision>
      <geometry>
        <sphere radius="0.2"/>
      </geometry>
    </collision>
    <inertial>
      <mass value="35"/>
      <inertia ixx="0.56" ixy="0.0" ixz="0.0" iyy="0.56" iyz="0.0" izz="0.56"/>
    </inertial>
  </link>
  <joint name="stomach_to_base" type="fixed">
    <parent link="base_link"/>
    <child link="stomach"/>
    <origin xyz="0 0 0.2"/>
  </joint>
  <link name="right_leg">
    <visual>
      <origin xyz="0 0 0.1"/>
      <geometry>
        <cylinder length="0.2" radius="0.05"/>
      </geometry>
      <material name="violet"/>
    </visual>
    <collision>
      <origin xyz="0 0 0.1"/>
      <geometry>
        <cylinder length="0.2" radius="0.05"/>
      </geometry>
    </collision>
    <inertial>
      <origin xyz="0 0 0.1"/>
      <mass value="1"/>
      <inertia ixx="0.003958333333333334" ixy="0" ixz="0" iyy="0.003958333333333334" iyz="0" izz="0.0012500000000000002"/>
    </inertial>
  </link>
  <joint name="stomach_to_right_leg" type="revolute">
    <axis xyz="0 1 0"/>
    <limit effort="1000.0" lower="-0.7853981633974483" upper="1.5707963267948966" velocity="0.5"/>
    <parent link="stomach"/>
    <child link="right_leg"/>
    <origin rpy="0 1.5707963267948966 0" xyz="0.1 -0.1 -0.1"/>
  </joint>
  <link name="left_leg">
    <visual>
      <origin xyz="0 0 0.1"/>
      <geometry>
        <cylinder length="0.2" radius="0.05"/>
      </geometry>
      <material name="violet"/>
    </visual>
    <collision>
      <origin xyz="0 0 0.1"/>
      <geometry>
        <cylinder length="0.2" radius="0.05"/>
      </geometry>
    </collision>
    <inertial>
      <origin xyz="0 0 0.1"/>
      <mass value="1"/>
      <inertia ixx="0.003958333333333334" ixy="0" ixz="0" iyy="0.003958333333333334" iyz="0" izz="0.0012500000000000002"/>
    </inertial>
  </link>
  <joint name="stomach_to_left_leg" type="revolute">
    <axis xyz="0 1 0"/>
    <limit effort="1000.0" lower="-0.7853981633974483" upper="1.5707963267948966" velocity="0.5"/>
    <parent link="stomach"/>
    <child link="left_leg"/>
    <origin rpy="0 1.5707963267948966 0" xyz="0.1 0.1 -0.1"/>
  </joint>
  <link name="right_wheel">
    <visual>
      <geometry>
        <sphere radius="0.07"/>
      </geometry>
      <material name="white"/>
    </visual>
    <collision>
      <geometry>
        <sphere radius="0.07"/>
      </geometry>
    </collision>
    <inertial>
      <mass value="0.2"/>
      <inertia ixx="0.00039200000000000015" ixy="0.0" ixz="0.0" iyy="0.00039200000000000015" iyz="0.0" izz="0.00039200000000000015"/>
    </inertial>
  </link>
  <joint name="right_wheel_joint" type="continuous">
    <axis xyz="0 1 0"/>
    <parent link="right_leg"/>
    <child link="right_wheel"/>
    <origin xyz="0 0 0.2"/>
  </joint>
  <link name="left_wheel">
    <visual>
      <geometry>
        <sphere radius="0.07"/>
      </geometry>
      <material name="white"/>
    </visual>
    <collision>
      <geometry>
        <sphere radius="0.07"/>
      </geometry>
    </collision>
    <inertial>
      <mass value="0.2"/>
      <inertia ixx="0.00039200000000000015" ixy="0.0" ixz="0.0" iyy="0.00039200000000000015" iyz="0.0" izz="0.00039200000000000015"/>
    </inertial>
  </link>
  <joint name="left_wheel_joint" type="continuous">
    <axis xyz="0 1 0"/>
    <parent link="left_leg"/>
    <child link="left_wheel"/>
    <origin xyz="0 0 0.2"/>
  </joint>
  <link name="right_arm">
    <visual>
      <origin xyz="0 0 0.1"/>
      <geometry>
        <cylinder length="0.2" radius="0.035"/>
      </geometry>
      <material name="plum"/>
    </visual>
    <collision>
      <origin xyz="0 0 0.1"/>
      <geometry>
        <cylinder length="0.2" radius="0.035"/>
      </geometry>
    </collision>
    <inertial>
      <origin xyz="0 0 0.1"/>
      <mass value="0.8"/>
      <inertia ixx="0.002911666666666667" ixy="0" ixz="0" iyy="0.002911666666666667" iyz="0" izz="0.0004900000000000001"/>
    </inertial>
  </link>
  <joint name="right_arm_joint" type="revolute">
    <axis xyz="1 0 0"/>
    <limit effort="1000.0" lower="-0.7853981633974483" upper="0.7853981633974483" velocity="0.5"/>
    <parent link="stomach"/>
    <child link="right_arm"/>
    <origin rpy="1.5707963267948966 0 0" xyz="0 -0.15000000000000002 0.05"/>
  </joint>
  <link name="right_paw">
    <visual>
      <geometry>
        <sphere radius="0.04"/>
      </geometry>
      <material name="white"/>
    </visual>
    <collision>
      <geometry>
        <sphere radius="0.04"/>
      </geometry>
    </collision>
    <inertial>
      <mass value="0.1"/>
      <inertia ixx="6.400000000000001e-05" ixy="0.0" ixz="0.0" iyy="6.400000000000001e-05" iyz="0.0" izz="6.400000000000001e-05"/>
    </inertial>
  </link>
  <joint name="right_paw_joint" type="fixed">
    <parent link="right_arm"/>
    <child link="right_paw"/>
    <origin xyz="0 0 0.2"/>
  </joint>
  <link name="left_arm">
    <visual>
      <origin xyz="0 0 -0.1"/>
      <geometry>
        <cylinder length="0.2" radius="0.035"/>
      </geometry>
      <material name="plum"/>
    </visual>
    <collision>
      <origin xyz="0 0 -0.1"/>
      <geometry>
        <cylinder length="0.2" radius="0.035"/>
      </geometry>
    </collision>
    <inertial>
      <origin xyz="0 0 -0.1"/>
      <mass value="0.8"/>
      <inertia ixx="0.002911666666666667" ixy="0" ixz="0" iyy="0.002911666666666667" iyz="0" izz="0.0004900000000000001"/>
    </inertial>
  </link>
  <joint name="left_arm_joint" type="revolute">
    <axis xyz="1 0 0"/>
    <limit effort="1000.0" lower="-0.7853981633974483" upper="0.7853981633974483" velocity="0.5"/>
    <parent link="stomach"/>
    <child link="left_arm"/>
    <origin rpy="1.5707963267948966 0 0" xyz="0 0.15000000000000002 0.05"/>
  </joint>
  <link name="left_paw">
    <visual>
      <geometry>
        <sphere radius="0.04"/>
      </geometry>
      <material name="white"/>
    </visual>
    <collision>
      <geometry>
        <sphere radius="0.04"/>
      </geometry>
    </collision>
    <inertial>
      <mass value="0.1"/>
      <inertia ixx="6.400000000000001e-05" ixy="0.0" ixz="0.0" iyy="6.400000000000001e-05" iyz="0.0" izz="6.400000000000001e-05"/>
    </inertial>
  </link>
  <joint name="left_paw_joint" type="fixed">
    <parent link="left_arm"/>
    <child link="left_paw"/>
    <origin xyz="0 0 -0.2"/>
  </joint>
  <!-- Define neck -->
  <link name="neck">
    <visual>
      <geometry>
        <cylinder length="0.08" radius="0.15"/>
      </geometry>
      <material name="plum"/>
    </visual>
    <collision>
      <geometry>
        <cylinder length="0.08" radius="0.15"/>
      </geometry>
    </collision>
    <inertial>
      <mass value="1.5"/>
      <inertia ixx="0.0092375" ixy="0" ixz="0" iyy="0.0092375" iyz="0" izz="0.016875"/>
    </inertial>
  </link>
  <joint name="neck_joint" type="fixed">
    <parent link="stomach"/>
    <child link="neck"/>
    <origin xyz="0 0 0.2"/>
  </joint>
  <!-- Define head -->
  <link name="head">
    <visual>
      <geometry>
        <sphere radius="0.15"/>
      </geometry>
      <material name="plum"/>
    </visual>
    <collision>
      <geometry>
        <sphere radius="0.15"/>
      </geometry>
    </collision>
    <inertial>
      <mass value="3"/>
      <inertia ixx="0.027000000000000003" ixy="0.0" ixz="0.0" iyy="0.027000000000000003" iyz="0.0" izz="0.027000000000000003"/>
    </inertial>
  </link>
  <joint name="head_swivel" type="revolute">
    <parent link="neck"/>
    <child link="head"/>
    <axis xyz="0 0 1"/>
    <limit effort="1000.0" lower="-1.5707963267948966" upper="1.5707963267948966" velocity="0.5"/>
    <origin xyz="0 0 0.15"/>
  </joint>
  <link name="right_lower_ear">
    <visual>
      <origin xyz="0 0 0.05"/>
      <geometry>
        <cylinder length="0.1" radius="0.045"/>
      </geometry>
      <material name="violet"/>
    </visual>
    <collision>
      <origin xyz="0 0 0.05"/>
      <geometry>
        <cylinder length="0.1" radius="0.045"/>
      </geometry>
    </collision>
    <inertial>
      <origin xyz="0 0 0.05"/>
      <mass value="0.5"/>
      <inertia ixx="0.0006697916666666667" ixy="0" ixz="0" iyy="0.0006697916666666667" iyz="0" izz="0.00050625"/>
    </inertial>
  </link>
  <joint name="right_lower_ear_joint" type="revolute">
    <axis xyz="1 0 0"/>
    <limit effort="1000.0" lower="-0.05235987755982989" upper="0.05235987755982989" velocity="0.5"/>
    <parent link="head"/>
    <child link="right_lower_ear"/>
    <origin rpy="1.4835298641951802 0 0" xyz="0 -0.1 0.05"/>
  </joint>
  <link name="right_lower_ear_tip">
    <visual>
      <geometry>
        <sphere radius="0.045"/>
      </geometry>
      <material name="violet"/>
    </visual>
    <collision>
      <geometry>
        <sphere radius="0.045"/>
      </geometry>
    </collision>
    <inertial>
      <mass value="0.5"/>
      <inertia ixx="0.000405" ixy="0.0" ixz="0.0" iyy="0.000405" iyz="0.0" izz="0.000405"/>
    </inertial>
  </link>
  <joint name="right_lower_ear_tip_joint" type="fixed">
    <parent link="right_lower_ear"/>
    <child link="right_lower_ear_tip"/>
    <origin xyz="0 0 0.1"/>
  </joint>
  <link name="right_upper_ear">
    <visual>
      <origin xyz="0 0 0.05"/>
      <geometry>
        <cylinder length="0.1" radius="0.045"/>
      </geometry>
      <material name="violet"/>
    </visual>
    <collision>
      <origin xyz="0 0 0.05"/>
      <geometry>
        <cylinder length="0.1" radius="0.045"/>
      </geometry>
    </collision>
    <inertial>
      <origin xyz="0 0 0.05"/>
      <mass value="0.5"/>
      <inertia ixx="0.0006697916666666667" ixy="0" ixz="0" iyy="0.0006697916666666667" iyz="0" izz="0.00050625"/>
    </inertial>
  </link>
  <joint name="right_upper_ear_joint" type="revolute">
    <axis xyz="1 0 0"/>
    <limit effort="1000.0" lower="-0.05235987755982989" upper="0.05235987755982989" velocity="0.5"/>
    <parent link="head"/>
    <child link="right_upper_ear"/>
    <origin rpy="0.7853981633974483 0 0" xyz="0 -0.08 0.1"/>
  </joint>
  <link name="right_upper_ear_tip">
    <visual>
      <geometry>
        <sphere radius="0.045"/>
      </geometry>
      <material name="violet"/>
    </visual>
    <collision>
      <geometry>
        <sphere radius="0.045"/>
      </geometry>
    </collision>
    <inertial>
      <mass value="0.5"/>
      <inertia ixx="0.000405" ixy="0.0" ixz="0.0" iyy="0.000405" iyz="0.0" izz="0.000405"/>
    </inertial>
  </link>
  <joint name="right_upper_ear_tip_joint" type="fixed">
    <parent link="right_upper_ear"/>
    <child link="right_upper_ear_tip"/>
    <origin xyz="0 0 0.1"/>
  </joint>
  <link name="left_lower_ear">
    <visual>
      <origin xyz="0 0 -0.05"/>
      <geometry>
        <cylinder length="0.1" radius="0.045"/>
      </geometry>
      <material name="violet"/>
    </visual>
    <collision>
      <origin xyz="0 0 -0.05"/>
      <geometry>
        <cylinder length="0.1" radius="0.045"/>
      </geometry>
    </collision>
    <inertial>
      <origin xyz="0 0 -0.05"/>
      <mass value="0.5"/>
      <inertia ixx="0.0006697916666666667" ixy="0" ixz="0" iyy="0.0006697916666666667" iyz="0" izz="0.00050625"/>
    </inertial>
  </link>
  <joint name="left_lower_ear_joint" type="revolute">
    <axis xyz="1 0 0"/>
    <limit effort="1000.0" lower="-0.05235987755982989" upper="0.05235987755982989" velocity="0.5"/>
    <parent link="head"/>
    <child link="left_lower_ear"/>
    <origin rpy="1.6580627893946132 0 0" xyz="0 0.1 0.05"/>
  </joint>
  <link name="left_lower_ear_tip">
    <visual>
      <geometry>
        <sphere radius="0.045"/>
      </geometry>
      <material name="violet"/>
    </visual>
    <collision>
      <geometry>
        <sphere radius="0.045"/>
      </geometry>
    </collision>
    <inertial>
      <mass value="0.5"/>
      <inertia ixx="0.000405" ixy="0.0" ixz="0.0" iyy="0.000405" iyz="0.0" izz="0.000405"/>
    </inertial>
  </link>
  <joint name="left_lower_ear_tip_joint" type="fixed">
    <parent link="left_lower_ear"/>
    <child link="left_lower_ear_tip"/>
    <origin xyz="0 0 -0.1"/>
  </joint>
  <link name="left_upper_ear">
    <visual>
      <origin xyz="0 0 -0.05"/>
      <geometry>
        <cylinder length="0.1" radius="0.045"/>
      </geometry>
      <material name="violet"/>
    </visual>
    <collision>
      <origin xyz="0 0 -0.05"/>
      <geometry>
        <cylinder length="0.1" radius="0.045"/>
      </geometry>
    </collision>
    <inertial>
      <origin xyz="0 0 -0.05"/>
      <mass value="0.5"/>
      <inertia ixx="0.0006697916666666667" ixy="0" ixz="0" iyy="0.0006697916666666667" iyz="0" izz="0.00050625"/>
    </inertial>
  </link>
  <joint name="left_upper_ear_joint" type="revolute">
    <axis xyz="1 0 0"/>
    <limit effort="1000.0" lower="-0.05235987755982989" upper="0.05235987755982989" velocity="0.5"/>
    <parent link="head"/>
    <child link="left_upper_ear"/>
    <origin rpy="2.356194490192345 0 0" xyz="0 0.08 0.1"/>
  </joint>
  <link name="left_upper_ear_tip">
    <visual>
      <geometry>
        <sphere radius="0.045"/>
      </geometry>
      <material name="violet"/>
    </visual>
    <collision>
      <geometry>
        <sphere radius="0.045"/>
      </geometry>
    </collision>
    <inertial>
      <mass value="0.5"/>
      <inertia ixx="0.000405" ixy="0.0" ixz="0.0" iyy="0.000405" iyz="0.0" izz="0.000405"/>
    </inertial>
  </link>
  <joint name="left_upper_ear_tip_joint" type="fixed">
    <parent link="left_upper_ear"/>
    <child link="left_upper_ear_tip"/>
    <origin xyz="0 0 -0.1"/>
  </joint>
</robot>

